Workbook
Name _xlcn.WorksheetConnection_Pivot_Store_DimA1B51: #REF!
Name _xlcn.WorksheetConnection_Customer_DimL1M5011: Customer_Dim!$L$1:$M$501

Sheet Customer_Dim
A1: Customer_ID | B1: Name | C1: Age | D1: Gender | E1: City | F1: State | G1: COUNTRY | H1: Loyalty_Level | I1: Clean_Name | J1: Clean_City | K1: Clean_State | L1: Clean_Gender | M1: Loyalty_Filled | N1: Age_Check
A2: CUST1000 | B2: sheena bonilla | C2: 55 | D2: Male | E2: Donaldton | F2: North Carolina | G2: USA | I2: =PROPER(B2) -> Sheena Bonilla | J2: =TRIM(PROPER(E2)) -> Donaldton | K2: =TRIM(PROPER(F2)) -> North Carolina | L2: =TRIM(PROPER(D2)) -> Male | M2: =IF(H2="","Standard",H2) -> Standard | N2: =IF(OR(C2<18,C2>70),"Check","OK") -> OK
A3: CUST1001 | B3: Eugene Nelson | C3: 26 | D3: Female | E3: Phillipsmouth | F3: North Dakota | G3: USA | H3: Platinum | I3: =PROPER(B3) -> Eugene Nelson | J3: =TRIM(PROPER(E3)) -> Phillipsmouth | K3: =TRIM(PROPER(F3)) -> North Dakota | L3: =TRIM(PROPER(D3)) -> Female | M3: =IF(H3="","Standard",H3) -> Platinum | N3: =IF(OR(C3<18,C3>70),"Check","OK") -> OK
A4: CUST1002 | B4: dr. Benjamin Price | C4: 29 | D4: Female | E4: Kylebury | F4: Alabama | G4: USA | H4: Platinum | I4: =PROPER(B4) -> Dr. Benjamin Price | J4: =TRIM(PROPER(E4)) -> Kylebury | K4: =TRIM(PROPER(F4)) -> Alabama | L4: =TRIM(PROPER(D4)) -> Female | M4: =IF(H4="","Standard",H4) -> Platinum | N4: =IF(OR(C4<18,C4>70),"Check","OK") -> OK
A5: CUST1003 | B5: jeremy harris | C5: 59 | D5: Female | E5: Thomastown | F5: Ohio | G5: USA | H5: Bronze | I5: =PROPER(B5) -> Jeremy Harris | J5: =TRIM(PROPER(E5)) -> Thomastown | K5: =TRIM(PROPER(F5)) -> Ohio | L5: =TRIM(PROPER(D5)) -> Female | M5: =IF(H5="","Standard",H5) -> Bronze | N5: =IF(OR(C5<18,C5>70),"Check","OK") -> OK
A6: CUST1004 | B6: Caroline Collins | C6: 64 | D6: Female | E6: Nicholasshire | F6: California | G6: USA | H6: Silver | I6: =PROPER(B6) -> Caroline Collins | J6: =TRIM(PROPER(E6)) -> Nicholasshire | K6: =TRIM(PROPER(F6)) -> California | L6: =TRIM(PROPER(D6)) -> Female | M6: =IF(H6="","Standard",H6) -> Silver | N6: =IF(OR(C6<18,C6>70),"Check","OK") -> OK
A7: CUST1005 | B7: Christine Vaughn | C7: 24 | D7: Male | E7: East Amandamouth | F7: Oregon | G7: USA | H7: Bronze | I7: =PROPER(B7) -> Christine Vaughn | J7: =TRIM(PROPER(E7)) -> East Amandamouth | K7: =TRIM(PROPER(F7)) -> Oregon | L7: =TRIM(PROPER(D7)) -> Male | M7: =IF(H7="","Standard",H7) -> Bronze | N7: =IF(OR(C7<18,C7>70),"Check","OK") -> OK
A8: CUST1006 | B8: Amber Jackson | C8: 29 | D8: Female | E8: Deborahborough | F8: South Dakota | G8: USA | H8: Platinum | I8: =PROPER(B8) -> Amber Jackson | J8: =TRIM(PROPER(E8)) -> Deborahborough | K8: =TRIM(PROPER(F8)) -> South Dakota | L8: =TRIM(PROPER(D8)) -> Female | M8: =IF(H8="","Standard",H8) -> Platinum | N8: =IF(OR(C8<18,C8>70),"Check","OK") -> OK
A9: CUST1007 | B9: Daniel Boyd | C9: 29 | D9: Female | E9: West Pamelafurt | F9: West Virginia | G9: USA | H9: Bronze | I9: =PROPER(B9) -> Daniel Boyd | J9: =TRIM(PROPER(E9)) -> West Pamelafurt | K9: =TRIM(PROPER(F9)) -> West Virginia | L9: =TRIM(PROPER(D9)) -> Female | M9: =IF(H9="","Standard",H9) -> Bronze | N9: =IF(OR(C9<18,C9>70),"Check","OK") -> OK
A10: CUST1008 | B10: Melissa Howard | C10: 53 | D10: Female | E10: Maynardton | F10: New Hampshire | G10: USA | H10: Gold | I10: =PROPER(B10) -> Melissa Howard | J10: =TRIM(PROPER(E10)) -> Maynardton | K10: =TRIM(PROPER(F10)) -> New Hampshire | L10: =TRIM(PROPER(D10)) -> Female | M10: =IF(H10="","Standard",H10) -> Gold | N10: =IF(OR(C10<18,C10>70),"Check","OK") -> OK
A11: CUST1009 | B11: Ms. Maria Leach | C11: 64 | D11: Male | E11: Melissashire | F11: Pennsylvania | G11: USA | H11: Platinum | I11: =PROPER(B11) -> Ms. Maria Leach | J11: =TRIM(PROPER(E11)) -> Melissashire | K11: =TRIM(PROPER(F11)) -> Pennsylvania | L11: =TRIM(PROPER(D11)) -> Male | M11: =IF(H11="","Standard",H11) -> Platinum | N11: =IF(OR(C11<18,C11>70),"Check","OK") -> OK
A12: CUST1010 | B12: Dominic Page | C12: 53 | D12: Male | E12: Port Michaelburgh | F12: Pennsylvania | G12: USA | H12: Bronze | I12: =PROPER(B12) -> Dominic Page | J12: =TRIM(PROPER(E12)) -> Port Michaelburgh | K12: =TRIM(PROPER(F12)) -> Pennsylvania | L12: =TRIM(PROPER(D12)) -> Male | M12: =IF(H12="","Standard",H12) -> Bronze | N12: =IF(OR(C12<18,C12>70),"Check","OK") -> OK
A13: CUST1011 | B13: Brian Lopez | C13: 28 | D13: Female | E13: East Krista | F13: New York | G13: USA | H13: Gold | I13: =PROPER(B13) -> Brian Lopez | J13: =TRIM(PROPER(E13)) -> East Krista | K13: =TRIM(PROPER(F13)) -> New York | L13: =TRIM(PROPER(D13)) -> Female | M13: =IF(H13="","Standard",H13) -> Gold | N13: =IF(OR(C13<18,C13>70),"Check","OK") -> OK
A14: CUST1012 | B14: Kenneth Lambert | C14: 55 | D14: Female | E14: North Kathryn | F14: Kansas | G14: USA | H14: Platinum | I14: =PROPER(B14) -> Kenneth Lambert | J14: =TRIM(PROPER(E14)) -> North Kathryn | K14: =TRIM(PROPER(F14)) -> Kansas | L14: =TRIM(PROPER(D14)) -> Female | M14: =IF(H14="","Standard",H14) -> Platinum | N14: =IF(OR(C14<18,C14>70),"Check","OK") -> OK
... A19: CUST1017 | B19: Adam Cruz | C19: 60 | D19: Female | E19: Brandonville | F19: Georgia | G19: USA | H19: Platinum | I19: =PROPER(B19) -> Adam Cruz | J19: =TRIM(PROPER(E19)) -> Brandonville | K19: =TRIM(PROPER(F19)) -> Georgia | L19: =TRIM(PROPER(D19)) -> Female | M19: =IF(H19="","Standard",H19) -> Platinum | N19: =IF(OR(C19<18,C19>70),"Check","OK") -> OK
A20: CUST1018 | B20: Rhonda Moss | C20: 43 | D20: Male | E20: South William | F20: Kansas | G20: USA | I20: =PROPER(B20) -> Rhonda Moss | J20: =TRIM(PROPER(E20)) -> South William | K20: =TRIM(PROPER(F20)) -> Kansas | L20: =TRIM(PROPER(D20)) -> Male | M20: =IF(H20="","Standard",H20) -> Standard | N20: =IF(OR(C20<18,C20>70),"Check","OK") -> OK
A21: CUST1019 | B21: Michael Torres | C21: 46 | D21: Female | E21: Gonzalezfort | F21: New Jersey | G21: USA | H21: Platinum | I21: =PROPER(B21) -> Michael Torres | J21: =TRIM(PROPER(E21)) -> Gonzalezfort | K21: =TRIM(PROPER(F21)) -> New Jersey | L21: =TRIM(PROPER(D21)) -> Female | M21: =IF(H21="","Standard",H21) -> Platinum | N21: =IF(OR(C21<18,C21>70),"Check","OK") -> OK
A22: CUST1020 | B22: Bridget Allen | C22: 59 | D22: Male | E22: Lake Shaneburgh | F22: Delaware | G22: USA | H22: Silver | I22: =PROPER(B22) -> Bridget Allen | J22: =TRIM(PROPER(E22)) -> Lake Shaneburgh | K22: =TRIM(PROPER(F22)) -> Delaware | L22: =TRIM(PROPER(D22)) -> Male | M22: =IF(H22="","Standard",H22) -> Silver | N22: =IF(OR(C22<18,C22>70),"Check","OK") -> OK
A23: CUST1021 | B23: Jeff Martinez | C23: 36 | D23: Female | E23: Smithburgh | F23: Oklahoma | G23: USA | H23: Gold | I23: =PROPER(B23) -> Jeff Martinez | J23: =TRIM(PROPER(E23)) -> Smithburgh | K23: =TRIM(PROPER(F23)) -> Oklahoma | L23: =TRIM(PROPER(D23)) -> Female | M23: =IF(H23="","Standard",H23) -> Gold | N23: =IF(OR(C23<18,C23>70),"Check","OK") -> OK
A24: CUST1022 | B24: paul fox | C24: 33 | D24: Female | E24: Michaelton | F24: Hawaii | G24: USA | H24: Silver | I24: =PROPER(B24) -> Paul Fox | J24: =TRIM(PROPER(E24)) -> Michaelton | K24: =TRIM(PROPER(F24)) -> Hawaii | L24: =TRIM(PROPER(D24)) -> Female | M24: =IF(H24="","Standard",H24) -> Silver | N24: =IF(OR(C24<18,C24>70),"Check","OK") -> OK
A25: CUST1023 | B25: Jonathan Steele | C25: 52 | D25: Female | E25: Molinabury | F25: Oregon | G25: USA | H25: Silver | I25: =PROPER(B25) -> Jonathan Steele | J25: =TRIM(PROPER(E25)) -> Molinabury | K25: =TRIM(PROPER(F25)) -> Oregon | L25: =TRIM(PROPER(D25)) -> Female | M25: =IF(H25="","Standard",H25) -> Silver | N25: =IF(OR(C25<18,C25>70),"Check","OK") -> OK
A26: CUST1024 | B26: Heather Collins | C26: 40 | D26: Male | E26: Rogerschester | F26: Idaho | G26: USA | H26: Platinum | I26: =PROPER(B26) -> Heather Collins | J26: =TRIM(PROPER(E26)) -> Rogerschester | K26: =TRIM(PROPER(F26)) -> Idaho | L26: =TRIM(PROPER(D26)) -> Male | M26: =IF(H26="","Standard",H26) -> Platinum | N26: =IF(OR(C26<18,C26>70),"Check","OK") -> OK
A27: CUST1025 | B27: Diana Taylor | C27: 59 | D27: Female | E27: Vasqueztown | F27: California | G27: USA | H27: Bronze | I27: =PROPER(B27) -> Diana Taylor | J27: =TRIM(PROPER(E27)) -> Vasqueztown | K27: =TRIM(PROPER(F27)) -> California | L27: =TRIM(PROPER(D27)) -> Female | M27: =IF(H27="","Standard",H27) -> Bronze | N27: =IF(OR(C27<18,C27>70),"Check","OK") -> OK
A28: CUST1026 | B28: Amber Carlson | C28: 18 | D28: Female | E28: East Michellemouth | F28: Missouri | G28: USA | H28: Gold | I28: =PROPER(B28) -> Amber Carlson | J28: =TRIM(PROPER(E28)) -> East Michellemouth | K28: =TRIM(PROPER(F28)) -> Missouri | L28: =TRIM(PROPER(D28)) -> Female | M28: =IF(H28="","Standard",H28) -> Gold | N28: =IF(OR(C28<18,C28>70),"Check","OK") -> OK
A29: CUST1027 | B29: Leslie Johnson | C29: 31 | D29: Male | E29: Mollyshire | F29: Utah | G29: USA | I29: =PROPER(B29) -> Leslie Johnson | J29: =TRIM(PROPER(E29)) -> Mollyshire | K29: =TRIM(PROPER(F29)) -> Utah | L29: =TRIM(PROPER(D29)) -> Male | M29: =IF(H29="","Standard",H29) -> Standard | N29: =IF(OR(C29<18,C29>70),"Check","OK") -> OK
A30: CUST1028 | B30: Joshua Ryan | C30: 27 | D30: Female | E30: New David | F30: New Jersey | G30: USA | H30: Platinum | I30: =PROPER(B30) -> Joshua Ryan | J30: =TRIM(PROPER(E30)) -> New David | K30: =TRIM(PROPER(F30)) -> New Jersey | L30: =TRIM(PROPER(D30)) -> Female | M30: =IF(H30="","Standard",H30) -> Platinum | N30: =IF(OR(C30<18,C30>70),"Check","OK") -> OK
A31: CUST1029 | B31: David Arnold | C31: 54 | D31: Female | E31: East Jennifer | F31: California | G31: USA | H31: Silver | I31: =PROPER(B31) -> David Arnold | J31: =TRIM(PROPER(E31)) -> East Jennifer | K31: =TRIM(PROPER(F31)) -> California | L31: =TRIM(PROPER(D31)) -> Female | M31: =IF(H31="","Standard",H31) -> Silver | N31: =IF(OR(C31<18,C31>70),"Check","OK") -> OK
A32: CUST1030 | B32: Jessica Acevedo | C32: 64 | D32: Female | E32: Amybury | F32: Pennsylvania | G32: USA | H32: Bronze | I32: =PROPER(B32) -> Jessica Acevedo | J32: =TRIM(PROPER(E32)) -> Amybury | K32: =TRIM(PROPER(F32)) -> Pennsylvania | L32: =TRIM(PROPER(D32)) -> Female | M32: =IF(H32="","Standard",H32) -> Bronze | N32: =IF(OR(C32<18,C32>70),"Check","OK") -> OK
A33: CUST1031 | B33: Sarah Vance | C33: 41 | D33: Male | E33: Johnsonville | F33: Oregon | G33: USA | H33: Silver | I33: =PROPER(B33) -> Sarah Vance | J33: =TRIM(PROPER(E33)) -> Johnsonville | K33: =TRIM(PROPER(F33)) -> Oregon | L33: =TRIM(PROPER(D33)) -> Male | M33: =IF(H33="","Standard",H33) -> Silver | N33: =IF(OR(C33<18,C33>70),"Check","OK") -> OK
A34: CUST1032 | B34: Mike Jennings | C34: 48 | D34: Female | E34: Fostermouth | F34: Arizona | G34: USA | H34: Gold | I34: =PROPER(B34) -> Mike Jennings | J34: =TRIM(PROPER(E34)) -> Fostermouth | K34: =TRIM(PROPER(F34)) -> Arizona | L34: =TRIM(PROPER(D34)) -> Female | M34: =IF(H34="","Standard",H34) -> Gold | N34: =IF(OR(C34<18,C34>70),"Check","OK") -> OK
A35: CUST1033 | B35: Robert Jones DDS | C35: 25 | D35: Male | E35: Tristanton | F35: Oklahoma | G35: USA | H35: Platinum | I35: =PROPER(B35) -> Robert Jones Dds | J35: =TRIM(PROPER(E35)) -> Tristanton | K35: =TRIM(PROPER(F35)) -> Oklahoma | L35: =TRIM(PROPER(D35)) -> Male | M35: =IF(H35="","Standard",H35) -> Platinum | N35: =IF(OR(C35<18,C35>70),"Check","OK") -> OK
A36: CUST1034 | B36: Christopher Olson | C36: 27 | D36: Female | E36: West Richard | F36: Maryland | G36: USA | H36: Platinum | I36: =PROPER(B36) -> Christopher Olson | J36: =TRIM(PROPER(E36)) -> West Richard | K36: =TRIM(PROPER(F36)) -> Maryland | L36: =TRIM(PROPER(D36)) -> Female | M36: =IF(H36="","Standard",H36) -> Platinum | N36: =IF(OR(C36<18,C36>70),"Check","OK") -> OK
A37: CUST1035 | B37: Rachel Myers | C37: 52 | D37: Male | E37: Robertberg | F37: North Dakota | G37: USA | H37: Silver | I37: =PROPER(B37) -> Rachel Myers | J37: =TRIM(PROPER(E37)) -> Robertberg | K37: =TRIM(PROPER(F37)) -> North Dakota | L37: =TRIM(PROPER(D37)) -> Male | M37: =IF(H37="","Standard",H37) -> Silver | N37: =IF(OR(C37<18,C37>70),"Check","OK") -> OK
A38: CUST1036 | B38: Thomas Phillips | C38: 20 | D38: Female | E38: Luisfurt | F38: Georgia | G38: USA | H38: Gold | I38: =PROPER(B38) -> Thomas Phillips | J38: =TRIM(PROPER(E38)) -> Luisfurt | K38: =TRIM(PROPER(F38)) -> Georgia | L38: =TRIM(PROPER(D38)) -> Female | M38: =IF(H38="","Standard",H38) -> Gold | N38: =IF(OR(C38<18,C38>70),"Check","OK") -> OK
A39: CUST1037 | B39: Christopher Carter | C39: 27 | D39: Female | E39: Brendastad | F39: South Dakota | G39: USA | I39: =PROPER(B39) -> Christopher Carter | J39: =TRIM(PROPER(E39)) -> Brendastad | K39: =TRIM(PROPER(F39)) -> South Dakota | L39: =TRIM(PROPER(D39)) -> Female | M39: =IF(H39="","Standard",H39) -> Standard | N39: =IF(OR(C39<18,C39>70),"Check","OK") -> OK
A40: CUST1038 | B40: Deanna Simpson | C40: 35 | D40: Female | E40: Brownport | F40: North Dakota | G40: USA | H40: Bronze | I40: =PROPER(B40) -> Deanna Simpson | J40: =TRIM(PROPER(E40)) -> Brownport | K40: =TRIM(PROPER(F40)) -> North Dakota | L40: =TRIM(PROPER(D40)) -> Female | M40: =IF(H40="","Standard",H40) -> Bronze | N40: =IF(OR(C40<18,C40>70),"Check","OK") -> OK
A41: CUST1039 | B41: Tonya Reynolds | C41: 55 | D41: Female | E41: Darleneton | F41: Michigan | G41: USA | H41: Gold | I41: =PROPER(B41) -> Tonya Reynolds | J41: =TRIM(PROPER(E41)) -> Darleneton | K41: =TRIM(PROPER(F41)) -> Michigan | L41: =TRIM(PROPER(D41)) -> Female | M41: =IF(H41="","Standard",H41) -> Gold | N41: =IF(OR(C41<18,C41>70),"Check","OK") -> OK
A42: CUST1040 | B42: Eric Vega | C42: 50 | D42: Male | E42: Williamsonland | F42: Kansas | G42: USA | H42: Gold | I42: =PROPER(B42) -> Eric Vega | J42: =TRIM(PROPER(E42)) -> Williamsonland | K42: =TRIM(PROPER(F42)) -> Kansas | L42: =TRIM(PROPER(D42)) -> Male | M42: =IF(H42="","Standard",H42) -> Gold | N42: =IF(OR(C42<18,C42>70),"Check","OK") -> OK
A43: CUST1041 | B43: James Gibbs | C43: 21 | D43: Male | E43: Mooneyshire | F43: Alaska | G43: USA | H43: Platinum | I43: =PROPER(B43) -> James Gibbs | J43: =TRIM(PROPER(E43)) -> Mooneyshire | K43: =TRIM(PROPER(F43)) -> Alaska | L43: =TRIM(PROPER(D43)) -> Male | M43: =IF(H43="","Standard",H43) -> Platinum | N43: =IF(OR(C43<18,C43>70),"Check","OK") -> OK
A44: CUST1042 | B44: William Martin | C44: 19 | D44: Male | E44: Ryanburgh | F44: Connecticut | G44: USA | H44: Platinum | I44: =PROPER(B44) -> William Martin | J44: =TRIM(PROPER(E44)) -> Ryanburgh | K44: =TRIM(PROPER(F44)) -> Connecticut | L44: =TRIM(PROPER(D44)) -> Male | M44: =IF(H44="","Standard",H44) -> Platinum | N44: =IF(OR(C44<18,C44>70),"Check","OK") -> OK
...

Sheet Product_Dim
A1: Product_ID | B1: Product_Name | C1: Category | D1: Sub_Category | E1: Brand | F1: Cost | G1: Stock | I1: Clean_Product_Name | J1: Category_Filled | K1: Price_Check
A2: PROD0 | B2: Brother Laser Printer | C2: Electronics | D2: Computer | E2: Hunt Inc | F2: 112.42 | G2: 416 | I2: =PROPER(B2) -> Brother Laser Printer | J2: =IF(C2="","Others",C2) -> Electronics | K2: =IF(F2<=0,"Error","Valid") -> Valid
A3: PROD1 | B3: Men's Graphic T-Shirt | C3: Clothing | D3: Tops | E3: Terry-Moore | F3: 342.56 | G3: 181 | I3: =PROPER(B3) -> Men'S Graphic T-Shirt | J3: =IF(C3="","Others",C3) -> Clothing | K3: =IF(F3<=0,"Error","Valid") -> Valid
A4: PROD2 | B4: Women's Casual Hoodie | C4: Clothing | D4: Outerwear | E4: Sims Inc | G4: 352 | I4: =PROPER(B4) -> Women'S Casual Hoodie | J4: =IF(C4="","Others",C4) -> Clothing | K4: =IF(F4<=0,"Error","Valid") -> Error
A5: P-3 | B5: Men's Running Jacket | C5: Clothing | D5: Outerwear | E5: Pineda Ltd | F5: 364.67 | G5: 452 | I5: =PROPER(B5) -> Men'S Running Jacket | J5: =IF(C5="","Others",C5) -> Clothing | K5: =IF(F5<=0,"Error","Valid") -> Valid
A6: PROD4 | B6: Women's Yoga Pants | C6: Clothing | D6: Bottoms | E6: Gonzales-Davis | F6: 306.46 | G6: 487 | I6: =PROPER(B6) -> Women'S Yoga Pants | J6: =IF(C6="","Others",C6) -> Clothing | K6: =IF(F6<=0,"Error","Valid") -> Valid
A7: PROD5 | B7: Men's Leather Belt | C7: Clothing | D7: Accessories | E7: Baldwin, Garza and Gonzalez | F7: 261 | G7: 59 | I7: =PROPER(B7) -> Men'S Leather Belt | J7: =IF(C7="","Others",C7) -> Clothing | K7: =IF(F7<=0,"Error","Valid") -> Valid
A8: PROD6 | B8: Herbal Face Moisturizer | C8: Beauty | D8: Skincare | E8: Davidson PLC | F8: 312.8 | G8: 350 | I8: =PROPER(B8) -> Herbal Face Moisturizer | J8: =IF(C8="","Others",C8) -> Beauty | K8: =IF(F8<=0,"Error","Valid") -> Valid
A9: PROD7 | B9: LED Table Lamp | C9: Home | D9: Lighting | E9: Harrell LLC | F9: 218.86 | G9: 170 | I9: =PROPER(B9) -> Led Table Lamp | J9: =IF(C9="","Others",C9) -> Home | K9: =IF(F9<=0,"Error","Valid") -> Valid
A10: PROD8 | B10: Wireless Bluetooth Earbuds | C10: Electronics | D10: Audio | E10: Perez-Johnston | F10: 439.07 | G10: 142 | I10: =PROPER(B10) -> Wireless Bluetooth Earbuds | J10: =IF(C10="","Others",C10) -> Electronics | K10: =IF(F10<=0,"Error","Valid") -> Valid
A11: PROD9 | B11: Adjustable Dumbbell Set | C11: Sports | D11: Fitness | E11: Hill PLC | F11: 495.72 | G11: 323 | I11: =PROPER(B11) -> Adjustable Dumbbell Set | J11: =IF(C11="","Others",C11) -> Sports | K11: =IF(F11<=0,"Error","Valid") -> Valid
A12: PROD10 | B12: Ceramic Kitchen Bowl Set | C12: Home | D12: Kitchen | E12: Hamilton Group | F12: 298.86 | G12: 308 | I12: =PROPER(B12) -> Ceramic Kitchen Bowl Set | J12: =IF(C12="","Others",C12) -> Home | K12: =IF(F12<=0,"Error","Valid") -> Valid
A13: PROD11 | B13: HD Smart TV Stick | C13: Electronics | D13: Accessories | E13: Gibson, Hobbs and Weaver | F13: 449.4 | I13: =PROPER(B13) -> Hd Smart Tv Stick | J13: =IF(C13="","Others",C13) -> Electronics | K13: =IF(F13<=0,"Error","Valid") -> Valid
A14: PROD12 | B14: Hair Strengthening Shampoo | C14: Beauty | D14: Haircare | E14: Rice LLC | F14: 115.82 | G14: 460 | I14: =PROPER(B14) -> Hair Strengthening Shampoo | J14: =IF(C14="","Others",C14) -> Beauty | K14: =IF(F14<=0,"Error","Valid") -> Valid
A15: PROD13 | B15: USB-C Fast Charger | C15: Electronics | D15: Accessories | E15: Dawson-Perkins | F15: 242.23 | G15: 453 | I15: =PROPER(B15) -> Usb-C Fast Charger | J15: =IF(C15="","Others",C15) -> Electronics | K15: =IF(F15<=0,"Error","Valid") -> Valid
A16: PROD14 | B16: Decorative Wall Mirror | C16: Home | D16: Decor | E16: Luna, Anderson and Bowman | F16: 48.01 | G16: 439 | I16: =PROPER(B16) -> Decorative Wall Mirror | J16: =IF(C16="","Others",C16) -> Home | K16: =IF(F16<=0,"Error","Valid") -> Valid
A17: PROD15 | B17: 4K Home Projector | C17: Electronics | D17: Appliances | E17: Thomas LLC | F17: 465.34 | G17: 301 | I17: =PROPER(B17) -> 4K Home Projector | J17: =IF(C17="","Others",C17) -> Electronics | K17: =IF(F17<=0,"Error","Valid") -> Valid
A18: P-16 | B18: Beard Grooming Kit | C18: Beauty | D18: Grooming | E18: Erickson-Green | F18: 337.42 | G18: 256 | I18: =PROPER(B18) -> Beard Grooming Kit | J18: =IF(C18="","Others",C18) -> Beauty | K18: =IF(F18<=0,"Error","Valid") -> Valid
A19: PROD17 | B19: Soccer Training Cone Set | C19: Sports | D19: Accessories | E19: Ford, Murphy and Wilson | F19: 144.53 | G19: 367 | I19: =PROPER(B19) -> Soccer Training Cone Set | J19: =IF(C19="","Others",C19) -> Sports | K19: =IF(F19<=0,"Error","Valid") -> Valid
A20: PROD18 | B20: Women's Denim Jeans | C20: Clothing | D20: Bottoms | E20: Guerra-Hendrix | G20: 343 | I20: =PROPER(B20) -> Women'S Denim Jeans | J20: =IF(C20="","Others",C20) -> Clothing | K20: =IF(F20<=0,"Error","Valid") -> Error
A21: PROD19 | B21: Knee Support Brace | C21: Sports | D21: Equipment | E21: May-Reese | F21: 21.34 | G21: 65 | I21: =PROPER(B21) -> Knee Support Brace | J21: =IF(C21="","Others",C21) -> Sports | K21: =IF(F21<=0,"Error","Valid") -> Valid
A22: PROD20 | B22: Outdoor Sports Water Bottle | C22: Sports | D22: Accessories | E22: Soto-Ellis | F22: 131.51 | I22: =PROPER(B22) -> Outdoor Sports Water Bottle | J22: =IF(C22="","Others",C22) -> Sports | K22: =IF(F22<=0,"Error","Valid") -> Valid
A23: PROD21 | B23: Multi-Purpose Storage Box | C23: Home | D23: Storage | E23: Gardner-Montes | F23: 123.46 | G23: 76 | I23: =PROPER(B23) -> Multi-Purpose Storage Box | J23: =IF(C23="","Others",C23) -> Home | K23: =IF(F23<=0,"Error","Valid") -> Valid
A24: PROD22 | B24: Carbon Fiber Tennis Racket | C24: Sports | D24: Equipment | E24: Flores, Pineda and Rodriguez | F24: 484.62 | G24: 432 | I24: =PROPER(B24) -> Carbon Fiber Tennis Racket | J24: =IF(C24="","Others",C24) -> Sports | K24: =IF(F24<=0,"Error","Valid") -> Valid
A25: PROD23 | B25: Men's Formal Shirt | C25: Clothing | D25: Tops | E25: Moon, Mora and Santos | G25: 360 | I25: =PROPER(B25) -> Men'S Formal Shirt | J25: =IF(C25="","Others",C25) -> Clothing | K25: =IF(F25<=0,"Error","Valid") -> Error
A26: PROD24 | B26: Foldable Camping Chair | C26: Sports | D26: Outdoor | E26: Cook Ltd | F26: 166.06 | G26: 340 | I26: =PROPER(B26) -> Foldable Camping Chair | J26: =IF(C26="","Others",C26) -> Sports | K26: =IF(F26<=0,"Error","Valid") -> Valid
A27: PROD25 | B27: Women's Scarf Set | C27: Clothing | D27: Accessories | E27: Brown and Sons | F27: 174.02 | G27: 268 | I27: =PROPER(B27) -> Women'S Scarf Set | J27: =IF(C27="","Others",C27) -> Clothing | K27: =IF(F27<=0,"Error","Valid") -> Valid
A28: PROD26 | B28: Wireless Bluetooth Speaker | C28: Electronics | D28: Audio | E28: Reed-Schmidt | F28: 322.41 | G28: 213 | I28: =PROPER(B28) -> Wireless Bluetooth Speaker | J28: =IF(C28="","Others",C28) -> Electronics | K28: =IF(F28<=0,"Error","Valid") -> Valid
A29: PROD27 | B29: Decorative Floor Vase | C29: Home | D29: Decor | E29: Khan, Jones and Paul | G29: 378 | I29: =PROPER(B29) -> Decorative Floor Vase | J29: =IF(C29="","Others",C29) -> Home | K29: =IF(F29<=0,"Error","Valid") -> Error
A30: PROD28 | B30: Sports Stopwatch Timer | C30: Sports | D30: Accessories | E30: Burns-Hansen | F30: 38.76 | G30: 137 | I30: =PROPER(B30) -> Sports Stopwatch Timer | J30: =IF(C30="","Others",C30) -> Sports | K30: =IF(F30<=0,"Error","Valid") -> Valid
A31: PROD29 | B31: Fabric Sofa Throw Blanket | C31: Home | D31: Decor | E31: Hoffman Group | F31: 218.48 | G31: 276 | I31: =PROPER(B31) -> Fabric Sofa Throw Blanket | J31: =IF(C31="","Others",C31) -> Home | K31: =IF(F31<=0,"Error","Valid") -> Valid
A32: PROD30 | B32: Stainless Steel Cutlery Set | C32: Home | D32: Kitchen | E32: Stevens, Fernandez and Martin | F32: 19.52 | G32: 57 | I32: =PROPER(B32) -> Stainless Steel Cutlery Set | J32: =IF(C32="","Others",C32) -> Home | K32: =IF(F32<=0,"Error","Valid") -> Valid
A33: PROD31 | B33: Basketball | C33: Sports | D33: Team Sports | E33: Nolan-Snow | F33: 204.39 | G33: 281 | I33: =PROPER(B33) -> Basketball | J33: =IF(C33="","Others",C33) -> Sports | K33: =IF(F33<=0,"Error","Valid") -> Valid
A34: PROD32 | B34: Vitamin C Face Serum | C34: Beauty | D34: Skincare | E34: Griffin Ltd | F34: 283.83 | G34: 244 | I34: =PROPER(B34) -> Vitamin C Face Serum | J34: =IF(C34="","Others",C34) -> Beauty | K34: =IF(F34<=0,"Error","Valid") -> Valid
A35: PROD33 | B35: Modern Wall Clock | C35: Home | D35: Decor | E35: Weiss-Watson | F35: 179.77 | G35: 305 | I35: =PROPER(B35) -> Modern Wall Clock | J35: =IF(C35="","Others",C35) -> Home | K35: =IF(F35<=0,"Error","Valid") -> Valid
A36: PROD34 | B36: Gaming Mechanical Keyboard | C36: Electronics | D36: Computer | E36: Lucero LLC | F36: 419.28 | G36: 86 | I36: =PROPER(B36) -> Gaming Mechanical Keyboard | J36: =IF(C36="","Others",C36) -> Electronics | K36: =IF(F36<=0,"Error","Valid") -> Valid
A37: PROD35 | B37: Bedroom Table Lamp | C37: Home | D37: Lighting | E37: Jones LLC | F37: 382.22 | G37: 329 | I37: =PROPER(B37) -> Bedroom Table Lamp | J37: =IF(C37="","Others",C37) -> Home | K37: =IF(F37<=0,"Error","Valid") -> Valid
A38: PROD36 | B38: Women's Summer Dress | C38: Clothing | D38: Tops | E38: Smith-Mills | F38: 223.43 | G38: 154 | I38: =PROPER(B38) -> Women'S Summer Dress | J38: =IF(C38="","Others",C38) -> Clothing | K38: =IF(F38<=0,"Error","Valid") -> Valid
A39: PROD37 | B39: Men's Casual Sneakers | C39: Clothing | D39: Footwear | E39: Hogan-Lee | F39: 353.47 | G39: 214 | I39: =PROPER(B39) -> Men'S Casual Sneakers | J39: =IF(C39="","Others",C39) -> Clothing | K39: =IF(F39<=0,"Error","Valid") -> Valid
A40: PROD38 | B40: Sports Water Hydration Pack | C40: Sports | D40: Outdoor | E40: Sims-Smith | F40: 135.61 | G40: 394 | I40: =PROPER(B40) -> Sports Water Hydration Pack | J40: =IF(C40="","Others",C40) -> Sports | K40: =IF(F40<=0,"Error","Valid") -> Valid
...

Sheet Store_Dim
A1: Store_ID | B1: Region | C1: City | D1: Store_Type | F1: Clean_Store_ID | G1: Store_ID_Length | H1: Region_Store_Count | I1: Store_Key | J1: Validation
A2: STORE0 | B2: East | C2: Washingtonfurt | D2: Flagship | F2: =UPPER(TRIM(A2)) -> STORE0 | G2: =LEN(A2) -> 6 | H2: =COUNTIF(B:B,B2) -> 6 | I2: =A2&"-"&C2 -> STORE0-Washingtonfurt | J2: =IF(A2="","Missing ID","OK") -> OK
A3: STORE1 | B3: North | C3: Danielmouth | D3: Flagship | F3: =UPPER(TRIM(A3)) -> STORE1 | G3: =LEN(A3) -> 6 | H3: =COUNTIF(B:B,B3) -> 6 | I3: =A3&"-"&C3 -> STORE1-Danielmouth | J3: =IF(A3="","Missing ID","OK") -> OK
A4: STORE2 | B4: South | C4: North Nancyview | D4: Outlet | F4: =UPPER(TRIM(A4)) -> STORE2 | G4: =LEN(A4) -> 6 | H4: =COUNTIF(B:B,B4) -> 6 | I4: =A4&"-"&C4 -> STORE2-North Nancyview | J4: =IF(A4="","Missing ID","OK") -> OK
A5: STORE3 | B5: North | C5: Hoodberg | D5: Outlet | F5: =UPPER(TRIM(A5)) -> STORE3 | G5: =LEN(A5) -> 6 | H5: =COUNTIF(B:B,B5) -> 6 | I5: =A5&"-"&C5 -> STORE3-Hoodberg | J5: =IF(A5="","Missing ID","OK") -> OK
A6: STORE4 | B6: South | C6: Port Sharon | D6: Online | F6: =UPPER(TRIM(A6)) -> STORE4 | G6: =LEN(A6) -> 6 | H6: =COUNTIF(B:B,B6) -> 6 | I6: =A6&"-"&C6 -> STORE4-Port Sharon | J6: =IF(A6="","Missing ID","OK") -> OK
A7: STORE5 | B7: North | C7: New Michaelchester | D7: Outlet | F7: =UPPER(TRIM(A7)) -> STORE5 | G7: =LEN(A7) -> 6 | H7: =COUNTIF(B:B,B7) -> 6 | I7: =A7&"-"&C7 -> STORE5-New Michaelchester | J7: =IF(A7="","Missing ID","OK") -> OK
A8: STORE6 | B8: East | C8: Port Josephberg | D8: Online | F8: =UPPER(TRIM(A8)) -> STORE6 | G8: =LEN(A8) -> 6 | H8: =COUNTIF(B:B,B8) -> 6 | I8: =A8&"-"&C8 -> STORE6-Port Josephberg | J8: =IF(A8="","Missing ID","OK") -> OK
A9: STORE7 | B9: South | C9: Williamsfurt | D9: Online | F9: =UPPER(TRIM(A9)) -> STORE7 | G9: =LEN(A9) -> 6 | H9: =COUNTIF(B:B,B9) -> 6 | I9: =A9&"-"&C9 -> STORE7-Williamsfurt | J9: =IF(A9="","Missing ID","OK") -> OK
A10: STORE8 | B10: West | C10: Thompsonborough | D10: Online | F10: =UPPER(TRIM(A10)) -> STORE8 | G10: =LEN(A10) -> 6 | H10: =COUNTIF(B:B,B10) -> 2 | I10: =A10&"-"&C10 -> STORE8-Thompsonborough | J10: =IF(A10="","Missing ID","OK") -> OK
A11: STORE9 | B11: South | C11: East Johnstad | D11: Flagship | F11: =UPPER(TRIM(A11)) -> STORE9 | G11: =LEN(A11) -> 6 | H11: =COUNTIF(B:B,B11) -> 6 | I11: =A11&"-"&C11 -> STORE9-East Johnstad | J11: =IF(A11="","Missing ID","OK") -> OK
A12: STORE10 | B12: East | C12: East Davidville | D12: Online | F12: =UPPER(TRIM(A12)) -> STORE10 | G12: =LEN(A12) -> 7 | H12: =COUNTIF(B:B,B12) -> 6 | I12: =A12&"-"&C12 -> STORE10-East Davidville | J12: =IF(A12="","Missing ID","OK") -> OK
A13: STORE11 | B13: South | C13: Lake Michael | D13: Online | F13: =UPPER(TRIM(A13)) -> STORE11 | G13: =LEN(A13) -> 7 | H13: =COUNTIF(B:B,B13) -> 6 | I13: =A13&"-"&C13 -> STORE11-Lake Michael | J13: =IF(A13="","Missing ID","OK") -> OK
... A21: STORE19 | B21: East | C21: Vasquezborough | D21: Online | F21: =UPPER(TRIM(A21)) -> STORE19 | G21: =LEN(A21) -> 7 | H21: =COUNTIF(B:B,B21) -> 6 | I21: =A21&"-"&C21 -> STORE19-Vasquezborough | J21: =IF(A21="","Missing ID","OK") -> OK

Sheet Sales_Fact
A1: Sales_ID | B1: Order_Date | C1: Customer_ID | D1: Product_ID | E1: Store_ID | F1: Quantity | G1: Unit_Price | H1: Discount | I1: Total_Amount | J1: Net_Sales | K1: Month | L1: Year | N1: Customer_Name | O1: City | P1: Product_Name | Q1: Category | R1: Region | S1: Store_Type
A2: SALE0 | B2: 45480 | C2: CUST1409 | D2: PROD97 | E2: STORE3 | F2: 1 | G2: 218.04 | H2: 0.09 | I2: =F2*G2 -> 218.04 | J2: =H2*(1-I2) -> -19.5336 | K2: =TEXT(B2,"mmm") -> Jul | L2: =YEAR(B2) -> 2024 | N2: {=XLOOKUP(C2,Customer_Dim!A:A,Customer_Dim!B:B,"Not Found")} -> Sarah Smith | O2: {=XLOOKUP(C2,Customer_Dim!A:A,Customer_Dim!E:E,"Not Found")} -> Kathleenport | P2: {=XLOOKUP(D2,Product_Dim!A:A,Product_Dim!B:B,"Not Found")} -> Cricket Bat | Q2: {=XLOOKUP(D2,Product_Dim!A:A,Product_Dim!C:C,"Not Found")} -> Sports | R2: {=XLOOKUP(E2,Store_Dim!A:A,Store_Dim!B:B,"Not Found")} -> North | S2: {=XLOOKUP(E2,Store_Dim!A:A,Store_Dim!D:D,"Not Found")} -> Outlet
A3: SALE1 | B3: 45481 | C3: CUST1467 | D3: PROD74 | E3: STORE17 | F3: 3 | G3: 104.47 | H3: 0.27 | I3: =F3*G3 -> 313.41 | J3: =H3*(1-I3) -> -84.3507 | K3: =TEXT(B3,"mmm") -> Jul | L3: =YEAR(B3) -> 2024 | N3: {=XLOOKUP(C3,Customer_Dim!A:A,Customer_Dim!B:B,"Not Found")} -> Michael Foley | O3: {=XLOOKUP(C3,Customer_Dim!A:A,Customer_Dim!E:E,"Not Found")} -> Oneillfurt | P3: {=XLOOKUP(D3,Product_Dim!A:A,Product_Dim!B:B,"Not Found")} -> Bluetooth Car Audio System | Q3: {=XLOOKUP(D3,Product_Dim!A:A,Product_Dim!C:C,"Not Found")} -> Electronics | R3: {=XLOOKUP(E3,Store_Dim!A:A,Store_Dim!B:B,"Not Found")} -> North | S3: {=XLOOKUP(E3,Store_Dim!A:A,Store_Dim!D:D,"Not Found")} -> Flagship
A4: SALE2 | B4: 45482 | C4: CUST1056 | D4: PROD49 | E4: STORE8 | F4: 4 | G4: 914.05 | H4: 0.25 | I4: =F4*G4 -> 3656.2 | J4: =H4*(1-I4) -> -913.8 | K4: =TEXT(B4,"mmm") -> Jul | L4: =YEAR(B4) -> 2024 | N4: {=XLOOKUP(C4,Customer_Dim!A:A,Customer_Dim!B:B,"Not Found")} -> Christopher Sutton | O4: {=XLOOKUP(C4,Customer_Dim!A:A,Customer_Dim!E:E,"Not Found")} -> Deborahberg | P4: {=XLOOKUP(D4,Product_Dim!A:A,Product_Dim!B:B,"Not Found")} -> Men's Roll-On Perfume | Q4: {=XLOOKUP(D4,Product_Dim!A:A,Product_Dim!C:C,"Not Found")} -> Beauty | R4: {=XLOOKUP(E4,Store_Dim!A:A,Store_Dim!B:B,"Not Found")} -> West | S4: {=XLOOKUP(E4,Store_Dim!A:A,Store_Dim!D:D,"Not Found")} -> Online
A5: SALE3 | B5: 45483 | C5: CUST1346 | D5: PROD76 | E5: STORE8 | F5: 1 | G5: 921.51 | H5: 0.16 | I5: =F5*G5 -> 921.51 | J5: =H5*(1-I5) -> -147.2816 | K5: =TEXT(B5,"mmm") -> Jul | L5: =YEAR(B5) -> 2024 | N5: {=XLOOKUP(C5,Customer_Dim!A:A,Customer_Dim!B:B,"Not Found")} -> John Jordan | O5: {=XLOOKUP(C5,Customer_Dim!A:A,Customer_Dim!E:E,"Not Found")} -> Port Crystalberg | P5: {=XLOOKUP(D5,Product_Dim!A:A,Product_Dim!B:B,"Not Found")} -> Wireless Mouse | Q5: {=XLOOKUP(D5,Product_Dim!A:A,Product_Dim!C:C,"Not Found")} -> Electronics | R5: {=XLOOKUP(E5,Store_Dim!A:A,Store_Dim!B:B,"Not Found")} -> West | S5: {=XLOOKUP(E5,Store_Dim!A:A,Store_Dim!D:D,"Not Found")} -> Online
A6: SALE4 | B6: 45484 | C6: CUST1493 | D6: PROD59 | E6: STORE5 | F6: 3 | G6: 745.3 | H6: 0.18 | I6: =F6*G6 -> 2235.9 | J6: =H6*(1-I6) -> -402.282 | K6: =TEXT(B6,"mmm") -> Jul | L6: =YEAR(B6) -> 2024 | N6: {=XLOOKUP(C6,Customer_Dim!A:A,Customer_Dim!B:B,"Not Found")} -> Amanda Powell | O6: {=XLOOKUP(C6,Customer_Dim!A:A,Customer_Dim!E:E,"Not Found")} -> South William | P6: {=XLOOKUP(D6,Product_Dim!A:A,Product_Dim!B:B,"Not Found")} -> Men's Hair Styling Gel | Q6: {=XLOOKUP(D6,Product_Dim!A:A,Product_Dim!C:C,"Not Found")} -> Beauty | R6: {=XLOOKUP(E6,Store_Dim!A:A,Store_Dim!B:B,"Not Found")} -> North | S6: {=XLOOKUP(E6,Store_Dim!A:A,Store_Dim!D:D,"Not Found")} -> Outlet
A7: SALE5 | B7: 45485 | C7: CUST1116 | D7: PROD15 | E7: STORE7 | F7: 3 | G7: 147.01 | H7: 0.19 | I7: =F7*G7 -> 441.03 | J7: =H7*(1-I7) -> -83.6057 | K7: =TEXT(B7,"mmm") -> Jul | L7: =YEAR(B7) -> 2024 | N7: {=XLOOKUP(C7,Customer_Dim!A:A,Customer_Dim!B:B,"Not Found")} -> Anthony Phillips | O7: {=XLOOKUP(C7,Customer_Dim!A:A,Customer_Dim!E:E,"Not Found")} -> North Davidport | P7: {=XLOOKUP(D7,Product_Dim!A:A,Product_Dim!B:B,"Not Found")} -> 4K Home Projector | Q7: {=XLOOKUP(D7,Product_Dim!A:A,Product_Dim!C:C,"Not Found")} -> Electronics | R7: {=XLOOKUP(E7,Store_Dim!A:A,Store_Dim!B:B,"Not Found")} -> South | S7: {=XLOOKUP(E7,Store_Dim!A:A,Store_Dim!D:D,"Not Found")} -> Online
A8: SALE6 | B8: 45486 | C8: CUST1016 | D8: PROD56 | E8: STORE4 | F8: 2 | G8: 785.31 | H8: 0.15 | I8: =F8*G8 -> 1570.62 | J8: =H8*(1-I8) -> -235.443 | K8: =TEXT(B8,"mmm") -> Jul | L8: =YEAR(B8) -> 2024 | N8: {=XLOOKUP(C8,Customer_Dim!A:A,Customer_Dim!B:B,"Not Found")} -> John Scott | O8: {=XLOOKUP(C8,Customer_Dim!A:A,Customer_Dim!E:E,"Not Found")} -> South Christopher | P8: {=XLOOKUP(D8,Product_Dim!A:A,Product_Dim!B:B,"Not Found")} -> Premium Blanket Throw | Q8: {=XLOOKUP(D8,Product_Dim!A:A,Product_Dim!C:C,"Not Found")} -> Home | R8: {=XLOOKUP(E8,Store_Dim!A:A,Store_Dim!B:B,"Not Found")} -> South | S8: {=XLOOKUP(E8,Store_Dim!A:A,Store_Dim!D:D,"Not Found")} -> Online
A9: SALE7 | B9: 45487 | C9: CUST1152 | D9: PROD70 | E9: STORE8 | F9: 4 | G9: 342.39 | H9: 0.23 | I9: =F9*G9 -> 1369.56 | J9: =H9*(1-I9) -> -314.7688 | K9: =TEXT(B9,"mmm") -> Jul | L9: =YEAR(B9) -> 2024 | N9: {=XLOOKUP(C9,Customer_Dim!A:A,Customer_Dim!B:B,"Not Found")} -> Patrick Roberts | O9: {=XLOOKUP(C9,Customer_Dim!A:A,Customer_Dim!E:E,"Not Found")} -> Jaredville | P9: {=XLOOKUP(D9,Product_Dim!A:A,Product_Dim!B:B,"Not Found")} -> Kitchen Storage Rack | Q9: {=XLOOKUP(D9,Product_Dim!A:A,Product_Dim!C:C,"Not Found")} -> Home | R9: {=XLOOKUP(E9,Store_Dim!A:A,Store_Dim!B:B,"Not Found")} -> West | S9: {=XLOOKUP(E9,Store_Dim!A:A,Store_Dim!D:D,"Not Found")} -> Online
A10: SALE8 | B10: 45488 | C10: CUST1187 | D10: PROD99 | E10: STORE5 | G10: 448.25 | H10: 0.07 | I10: =F10*G10 -> 0 | J10: =H10*(1-I10) -> 0.07 | K10: =TEXT(B10,"mmm") -> Jul | L10: =YEAR(B10) -> 2024 | N10: {=XLOOKUP(C10,Customer_Dim!A:A,Customer_Dim!B:B,"Not Found")} -> Dr. Suzanne Bullock | O10: {=XLOOKUP(C10,Customer_Dim!A:A,Customer_Dim!E:E,"Not Found")} -> Lake Blaketon | P10: {=XLOOKUP(D10,Product_Dim!A:A,Product_Dim!B:B,"Not Found")} -> Stainless Steel Cookware Set | Q10: {=XLOOKUP(D10,Product_Dim!A:A,Product_Dim!C:C,"Not Found")} -> Home | R10: {=XLOOKUP(E10,Store_Dim!A:A,Store_Dim!B:B,"Not Found")} -> North | S10: {=XLOOKUP(E10,Store_Dim!A:A,Store_Dim!D:D,"Not Found")} -> Outlet
A11: SALE9 | B11: 45489 | C11: CUST1464 | D11: PROD33 | E11: STORE0 | F11: 2 | G11: 873.17 | H11: 0.23 | I11: =F11*G11 -> 1746.34 | J11: =H11*(1-I11) -> -401.4282 | K11: =TEXT(B11,"mmm") -> Jul | L11: =YEAR(B11) -> 2024 | N11: {=XLOOKUP(C11,Customer_Dim!A:A,Customer_Dim!B:B,"Not Found")} -> David Pierce | O11: {=XLOOKUP(C11,Customer_Dim!A:A,Customer_Dim!E:E,"Not Found")} -> Grayland | P11: {=XLOOKUP(D11,Product_Dim!A:A,Product_Dim!B:B,"Not Found")} -> Modern Wall Clock | Q11: {=XLOOKUP(D11,Product_Dim!A:A,Product_Dim!C:C,"Not Found")} -> Home | R11: {=XLOOKUP(E11,Store_Dim!A:A,Store_Dim!B:B,"Not Found")} -> East | S11: {=XLOOKUP(E11,Store_Dim!A:A,Store_Dim!D:D,"Not Found")} -> Flagship
A12: SALE10 | B12: 45490 | C12: CUST1065 | D12: PROD24 | E12: STORE14 | F12: 1 | G12: 278.63 | H12: 0.07 | I12: =F12*G12 -> 278.63 | J12: =H12*(1-I12) -> -19.4341 | K12: =TEXT(B12,"mmm") -> Jul | L12: =YEAR(B12) -> 2024 | N12: {=XLOOKUP(C12,Customer_Dim!A:A,Customer_Dim!B:B,"Not Found")} -> Michael Thomas | O12: {=XLOOKUP(C12,Customer_Dim!A:A,Customer_Dim!E:E,"Not Found")} -> Woodmouth | P12: {=XLOOKUP(D12,Product_Dim!A:A,Product_Dim!B:B,"Not Found")} -> Foldable Camping Chair | Q12: {=XLOOKUP(D12,Product_Dim!A:A,Product_Dim!C:C,"Not Found")} -> Sports | R12: {=XLOOKUP(E12,Store_Dim!A:A,Store_Dim!B:B,"Not Found")} -> South | S12: {=XLOOKUP(E12,Store_Dim!A:A,Store_Dim!D:D,"Not Found")} -> Outlet
A13: SALE11 | B13: 45491 | C13: CUST1320 | D13: PROD39 | E13: STORE1 | F13: 4 | G13: 286.92 | H13: 0.17 | I13: =F13*G13 -> 1147.68 | J13: =H13*(1-I13) -> -194.9356 | K13: =TEXT(B13,"mmm") -> Jul | L13: =YEAR(B13) -> 2024 | N13: {=XLOOKUP(C13,Customer_Dim!A:A,Customer_Dim!B:B,"Not Found")} -> Jessica Gonzalez | O13: {=XLOOKUP(C13,Customer_Dim!A:A,Customer_Dim!E:E,"Not Found")} -> South Darrenland | P13: {=XLOOKUP(D13,Product_Dim!A:A,Product_Dim!B:B,"Not Found")} -> Portable Power Bank | Q13: {=XLOOKUP(D13,Product_Dim!A:A,Product_Dim!C:C,"Not Found")} -> Electronics | R13: {=XLOOKUP(E13,Store_Dim!A:A,Store_Dim!B:B,"Not Found")} -> North | S13: {=XLOOKUP(E13,Store_Dim!A:A,Store_Dim!D:D,"Not Found")} -> Flagship
A14: SALE12 | B14: 45492 | C14: CUST1237 | D14: PROD88 | E14: STORE4 | F14: 4 | G14: 644.58 | H14: 0.01 | I14: =F14*G14 -> 2578.32 | J14: =H14*(1-I14) -> -25.7732 | K14: =TEXT(B14,"mmm") -> Jul | L14: =YEAR(B14) -> 2024 | N14: {=XLOOKUP(C14,Customer_Dim!A:A,Customer_Dim!B:B,"Not Found")} -> Wesley Short | O14: {=XLOOKUP(C14,Customer_Dim!A:A,Customer_Dim!E:E,"Not Found")} -> Susanstad | P14: {=XLOOKUP(D14,Product_Dim!A:A,Product_Dim!B:B,"Not Found")} -> Sports Wrist Sweatbands | Q14: {=XLOOKUP(D14,Product_Dim!A:A,Product_Dim!C:C,"Not Found")} -> Sports | R14: {=XLOOKUP(E14,Store_Dim!A:A,Store_Dim!B:B,"Not Found")} -> South | S14: {=XLOOKUP(E14,Store_Dim!A:A,Store_Dim!D:D,"Not Found")} -> Online
A15: SALE13 | B15: 45493 | C15: CUST1443 | D15: PROD34 | E15: STORE16 | F15: 2 | G15: 316.9 | H15: 0.3 | I15: =F15*G15 -> 633.8 | J15: =H15*(1-I15) -> -189.84 | K15: =TEXT(B15,"mmm") -> Jul | L15: =YEAR(B15) -> 2024 | N15: {=XLOOKUP(C15,Customer_Dim!A:A,Customer_Dim!B:B,"Not Found")} -> Adam Castro | O15: {=XLOOKUP(C15,Customer_Dim!A:A,Customer_Dim!E:E,"Not Found")} -> New Donnabury | P15: {=XLOOKUP(D15,Product_Dim!A:A,Product_Dim!B:B,"Not Found")} -> Gaming Mechanical Keyboard | Q15: {=XLOOKUP(D15,Product_Dim!A:A,Product_Dim!C:C,"Not Found")} -> Electronics | R15: {=XLOOKUP(E15,Store_Dim!A:A,Store_Dim!B:B,"Not Found")} -> West | S15: {=XLOOKUP(E15,Store_Dim!A:A,Store_Dim!D:D,"Not Found")} -> Flagship
A16: SALE14 | B16: 45494 | C16: CUST1348 | D16: PROD24 | E16: STORE15 | F16: 4 | G16: 403.47 | H16: 0.29 | I16: =F16*G16 -> 1613.88 | J16: =H16*(1-I16) -> -467.7352 | K16: =TEXT(B16,"mmm") -> Jul | L16: =YEAR(B16) -> 2024 | N16: {=XLOOKUP(C16,Customer_Dim!A:A,Customer_Dim!B:B,"Not Found")} -> Sherry Cabrera | O16: {=XLOOKUP(C16,Customer_Dim!A:A,Customer_Dim!E:E,"Not Found")} -> Shannonview | P16: {=XLOOKUP(D16,Product_Dim!A:A,Product_Dim!B:B,"Not Found")} -> Foldable Camping Chair | Q16: {=XLOOKUP(D16,Product_Dim!A:A,Product_Dim!C:C,"Not Found")} -> Sports | R16: {=XLOOKUP(E16,Store_Dim!A:A,Store_Dim!B:B,"Not Found")} -> North | S16: {=XLOOKUP(E16,Store_Dim!A:A,Store_Dim!D:D,"Not Found")} -> Flagship
A17: SALE15 | B17: 45495 | C17: CUST1435 | D17: PROD36 | E17: STORE9 | G17: 871.34 | H17: 0.04 | I17: =F17*G17 -> 0 | J17: =H17*(1-I17) -> 0.04 | K17: =TEXT(B17,"mmm") -> Jul | L17: =YEAR(B17) -> 2024 | N17: {=XLOOKUP(C17,Customer_Dim!A:A,Customer_Dim!B:B,"Not Found")} -> Lindsay Beasley | O17: {=XLOOKUP(C17,Customer_Dim!A:A,Customer_Dim!E:E,"Not Found")} -> Wesleyhaven | P17: {=XLOOKUP(D17,Product_Dim!A:A,Product_Dim!B:B,"Not Found")} -> Women's Summer Dress | Q17: {=XLOOKUP(D17,Product_Dim!A:A,Product_Dim!C:C,"Not Found")} -> Clothing | R17: {=XLOOKUP(E17,Store_Dim!A:A,Store_Dim!B:B,"Not Found")} -> South | S17: {=XLOOKUP(E17,Store_Dim!A:A,Store_Dim!D:D,"Not Found")} -> Flagship
A18: SALE16 | B18: 45496 | C18: CUST1276 | D18: PROD65 | E18: STORE19 | F18: 2 | G18: 451.98 | H18: 0.25 | I18: =F18*G18 -> 903.96 | J18: =H18*(1-I18) -> -225.74 | K18: =TEXT(B18,"mmm") -> Jul | L18: =YEAR(B18) -> 2024 | N18: {=XLOOKUP(C18,Customer_Dim!A:A,Customer_Dim!B:B,"Not Found")} -> Arthur Warren | O18: {=XLOOKUP(C18,Customer_Dim!A:A,Customer_Dim!E:E,"Not Found")} -> Ericshire | P18: {=XLOOKUP(D18,Product_Dim!A:A,Product_Dim!B:B,"Not Found")} -> Adjustable Dumbbells 20kg | Q18: {=XLOOKUP(D18,Product_Dim!A:A,Product_Dim!C:C,"Not Found")} -> Sports | R18: {=XLOOKUP(E18,Store_Dim!A:A,Store_Dim!B:B,"Not Found")} -> East | S18: {=XLOOKUP(E18,Store_Dim!A:A,Store_Dim!D:D,"Not Found")} -> Online
A19: SALE17 | B19: 45497 | C19: CUST1079 | D19: PROD27 | E19: STORE4 | F19: 2 | G19: 502.69 | H19: 0.23 | I19: =F19*G19 -> 1005.38 | J19: =H19*(1-I19) -> -231.0074 | K19: =TEXT(B19,"mmm") -> Jul | L19: =YEAR(B19) -> 2024 | N19: {=XLOOKUP(C19,Customer_Dim!A:A,Customer_Dim!B:B,"Not Found")} -> Molly Gardner | O19: {=XLOOKUP(C19,Customer_Dim!A:A,Customer_Dim!E:E,"Not Found")} -> Nicoleborough | P19: {=XLOOKUP(D19,Product_Dim!A:A,Product_Dim!B:B,"Not Found")} -> Decorative Floor Vase | Q19: {=XLOOKUP(D19,Product_Dim!A:A,Product_Dim!C:C,"Not Found")} -> Home | R19: {=XLOOKUP(E19,Store_Dim!A:A,Store_Dim!B:B,"Not Found")} -> South | S19: {=XLOOKUP(E19,Store_Dim!A:A,Store_Dim!D:D,"Not Found")} -> Online
A20: SALE18 | B20: 45498 | C20: CUST1094 | D20: PROD39 | E20: STORE4 | F20: 2 | G20: 559.23 | H20: 0.25 | I20: =F20*G20 -> 1118.46 | J20: =H20*(1-I20) -> -279.365 | K20: =TEXT(B20,"mmm") -> Jul | L20: =YEAR(B20) -> 2024 | N20: {=XLOOKUP(C20,Customer_Dim!A:A,Customer_Dim!B:B,"Not Found")} -> David Patterson | O20: {=XLOOKUP(C20,Customer_Dim!A:A,Customer_Dim!E:E,"Not Found")} -> New Amyport | P20: {=XLOOKUP(D20,Product_Dim!A:A,Product_Dim!B:B,"Not Found")} -> Portable Power Bank | Q20: {=XLOOKUP(D20,Product_Dim!A:A,Product_Dim!C:C,"Not Found")} -> Electronics | R20: {=XLOOKUP(E20,Store_Dim!A:A,Store_Dim!B:B,"Not Found")} -> South | S20: {=XLOOKUP(E20,Store_Dim!A:A,Store_Dim!D:D,"Not Found")} -> Online
A21: SALE19 | B21: 45499 | C21: CUST1239 | D21: PROD60 | E21: STORE13 | F21: 4 | H21: 0.04 | I21: =F21*G21 -> 0 | J21: =H21*(1-I21) -> 0.04 | K21: =TEXT(B21,"mmm") -> Jul | L21: =YEAR(B21) -> 2024 | N21: {=XLOOKUP(C21,Customer_Dim!A:A,Customer_Dim!B:B,"Not Found")} -> Maria Hill | O21: {=XLOOKUP(C21,Customer_Dim!A:A,Customer_Dim!E:E,"Not Found")} -> Zamoraborough | P21: {=XLOOKUP(D21,Product_Dim!A:A,Product_Dim!B:B,"Not Found")} -> Luxury Perfume Spray | Q21: {=XLOOKUP(D21,Product_Dim!A:A,Product_Dim!C:C,"Not Found")} -> Beauty | R21: {=XLOOKUP(E21,Store_Dim!A:A,Store_Dim!B:B,"Not Found")} -> East | S21: {=XLOOKUP(E21,Store_Dim!A:A,Store_Dim!D:D,"Not Found")} -> Flagship
A22: SALE20 | B22: 45500 | C22: CUST1144 | D22: PROD72 | E22: STORE17 | F22: 3 | G22: 986.04 | H22: 0.27 | I22: =F22*G22 -> 2958.12 | J22: =H22*(1-I22) -> -798.4224 | K22: =TEXT(B22,"mmm") -> Jul | L22: =YEAR(B22) -> 2024 | N22: {=XLOOKUP(C22,Customer_Dim!A:A,Customer_Dim!B:B,"Not Found")} -> Justin Cross | O22: {=XLOOKUP(C22,Customer_Dim!A:A,Customer_Dim!E:E,"Not Found")} -> North Anthonychester | P22: {=XLOOKUP(D22,Product_Dim!A:A,Product_Dim!B:B,"Not Found")} -> Professional Jump Rope | Q22: {=XLOOKUP(D22,Product_Dim!A:A,Product_Dim!C:C,"Not Found")} -> Sports | R22: {=XLOOKUP(E22,Store_Dim!A:A,Store_Dim!B:B,"Not Found")} -> North | S22: {=XLOOKUP(E22,Store_Dim!A:A,Store_Dim!D:D,"Not Found")} -> Flagship
A23: SALE21 | B23: 45501 | C23: CUST1396 | D23: PROD43 | E23: STORE18 | F23: 1 | G23: 589.56 | H23: 0.22 | I23: =F23*G23 -> 589.56 | J23: =H23*(1-I23) -> -129.4832 | K23: =TEXT(B23,"mmm") -> Jul | L23: =YEAR(B23) -> 2024 | N23: {=XLOOKUP(C23,Customer_Dim!A:A,Customer_Dim!B:B,"Not Found")} -> Alexander Byrd | O23: {=XLOOKUP(C23,Customer_Dim!A:A,Customer_Dim!E:E,"Not Found")} -> Parkerview | P23: {=XLOOKUP(D23,Product_Dim!A:A,Product_Dim!B:B,"Not Found")} -> USB External Hard Drive | Q23: {=XLOOKUP(D23,Product_Dim!A:A,Product_Dim!C:C,"Not Found")} -> Electronics | R23: {=XLOOKUP(E23,Store_Dim!A:A,Store_Dim!B:B,"Not Found")} -> East | S23: {=XLOOKUP(E23,Store_Dim!A:A,Store_Dim!D:D,"Not Found")} -> Flagship
A24: SALE22 | B24: 45502 | C24: CUST1476 | D24: PROD69 | E24: STORE10 | F24: 3 | G24: 979.42 | H24: 0.03 | I24: =F24*G24 -> 2938.26 | J24: =H24*(1-I24) -> -88.1178 | K24: =TEXT(B24,"mmm") -> Jul | L24: =YEAR(B24) -> 2024 | N24: {=XLOOKUP(C24,Customer_Dim!A:A,Customer_Dim!B:B,"Not Found")} -> Elizabeth Foster | O24: {=XLOOKUP(C24,Customer_Dim!A:A,Customer_Dim!E:E,"Not Found")} -> Anthonymouth | P24: {=XLOOKUP(D24,Product_Dim!A:A,Product_Dim!B:B,"Not Found")} -> Men's Sports Shorts | Q24: {=XLOOKUP(D24,Product_Dim!A:A,Product_Dim!C:C,"Not Found")} -> Clothing | R24: {=XLOOKUP(E24,Store_Dim!A:A,Store_Dim!B:B,"Not Found")} -> East | S24: {=XLOOKUP(E24,Store_Dim!A:A,Store_Dim!D:D,"Not Found")} -> Online
A25: SALE23 | B25: 45503 | C25: CUST1368 | D25: PROD12 | E25: STORE8 | F25: 1 | G25: 719.28 | H25: 0.08 | I25: =F25*G25 -> 719.28 | J25: =H25*(1-I25) -> -57.4624 | K25: =TEXT(B25,"mmm") -> Jul | L25: =YEAR(B25) -> 2024 | N25: {=XLOOKUP(C25,Customer_Dim!A:A,Customer_Dim!B:B,"Not Found")} -> Miranda King | O25: {=XLOOKUP(C25,Customer_Dim!A:A,Customer_Dim!E:E,"Not Found")} -> West Mathew | P25: {=XLOOKUP(D25,Product_Dim!A:A,Product_Dim!B:B,"Not Found")} -> Hair Strengthening Shampoo | Q25: {=XLOOKUP(D25,Product_Dim!A:A,Product_Dim!C:C,"Not Found")} -> Beauty | R25: {=XLOOKUP(E25,Store_Dim!A:A,Store_Dim!B:B,"Not Found")} -> West | S25: {=XLOOKUP(E25,Store_Dim!A:A,Store_Dim!D:D,"Not Found")} -> Online
A26: SALE24 | B26: 45504 | C26: CUST1186 | D26: PROD67 | E26: STORE6 | F26: 3 | G26: 77.6 | H26: 0.07 | I26: =F26*G26 -> 232.8 | J26: =H26*(1-I26) -> -16.226 | K26: =TEXT(B26,"mmm") -> Jul | L26: =YEAR(B26) -> 2024 | N26: {=XLOOKUP(C26,Customer_Dim!A:A,Customer_Dim!B:B,"Not Found")} -> Jennifer Pruitt | O26: {=XLOOKUP(C26,Customer_Dim!A:A,Customer_Dim!E:E,"Not Found")} -> East Justin | P26: {=XLOOKUP(D26,Product_Dim!A:A,Product_Dim!B:B,"Not Found")} -> Smart LED Light Strip | Q26: {=XLOOKUP(D26,Product_Dim!A:A,Product_Dim!C:C,"Not Found")} -> Electronics | R26: {=XLOOKUP(E26,Store_Dim!A:A,Store_Dim!B:B,"Not Found")} -> East | S26: {=XLOOKUP(E26,Store_Dim!A:A,Store_Dim!D:D,"Not Found")} -> Online
A27: SALE25 | B27: 45505 | C27: CUST1381 | D27: PROD5 | E27: STORE3 | F27: 4 | G27: 852.71 | H27: 0.14 | I27: =F27*G27 -> 3410.84 | J27: =H27*(1-I27) -> -477.3776 | K27: =TEXT(B27,"mmm") -> Aug | L27: =YEAR(B27) -> 2024 | N27: {=XLOOKUP(C27,Customer_Dim!A:A,Customer_Dim!B:B,"Not Found")} -> Erika Padilla | O27: {=XLOOKUP(C27,Customer_Dim!A:A,Customer_Dim!E:E,"Not Found")} -> Andrewsland | P27: {=XLOOKUP(D27,Product_Dim!A:A,Product_Dim!B:B,"Not Found")} -> Men's Leather Belt | Q27: {=XLOOKUP(D27,Product_Dim!A:A,Product_Dim!C:C,"Not Found")} -> Clothing | R27: {=XLOOKUP(E27,Store_Dim!A:A,Store_Dim!B:B,"Not Found")} -> North | S27: {=XLOOKUP(E27,Store_Dim!A:A,Store_Dim!D:D,"Not Found")} -> Outlet
A28: SALE26 | B28: 45506 | C28: CUST1213 | D28: PROD98 | E28: STORE8 | F28: 4 | G28: 156.16 | I28: =F28*G28 -> 624.64 | J28: =H28*(1-I28) -> 0 | K28: =TEXT(B28,"mmm") -> Aug | L28: =YEAR(B28) -> 2024 | N28: {=XLOOKUP(C28,Customer_Dim!A:A,Customer_Dim!B:B,"Not Found")} -> Stuart Johnson | O28: {=XLOOKUP(C28,Customer_Dim!A:A,Customer_Dim!E:E,"Not Found")} -> West Markport | P28: {=XLOOKUP(D28,Product_Dim!A:A,Product_Dim!B:B,"Not Found")} -> Portable Bluetooth Speaker | Q28: {=XLOOKUP(D28,Product_Dim!A:A,Product_Dim!C:C,"Not Found")} -> Electronics | R28: {=XLOOKUP(E28,Store_Dim!A:A,Store_Dim!B:B,"Not Found")} -> West | S28: {=XLOOKUP(E28,Store_Dim!A:A,Store_Dim!D:D,"Not Found")} -> Online
A29: SALE27 | B29: 45507 | C29: CUST1200 | D29: PROD77 | E29: STORE8 | F29: 3 | G29: 815.49 | H29: 0.17 | I29: =F29*G29 -> 2446.47 | J29: =H29*(1-I29) -> -415.7299 | K29: =TEXT(B29,"mmm") -> Aug | L29: =YEAR(B29) -> 2024 | N29: {=XLOOKUP(C29,Customer_Dim!A:A,Customer_Dim!B:B,"Not Found")} -> Anna Perez | O29: {=XLOOKUP(C29,Customer_Dim!A:A,Customer_Dim!E:E,"Not Found")} -> South Jerry | P29: {=XLOOKUP(D29,Product_Dim!A:A,Product_Dim!B:B,"Not Found")} -> WiFi Mesh Router | Q29: {=XLOOKUP(D29,Product_Dim!A:A,Product_Dim!C:C,"Not Found")} -> Electronics | R29: {=XLOOKUP(E29,Store_Dim!A:A,Store_Dim!B:B,"Not Found")} -> West | S29: {=XLOOKUP(E29,Store_Dim!A:A,Store_Dim!D:D,"Not Found")} -> Online
A30: SALE28 | B30: 45508 | C30: CUST1148 | D30: PROD13 | E30: STORE2 | F30: 2 | G30: 74.21 | H30: 0.11 | I30: =F30*G30 -> 148.42 | J30: =H30*(1-I30) -> -16.2162 | K30: =TEXT(B30,"mmm") -> Aug | L30: =YEAR(B30) -> 2024 | N30: {=XLOOKUP(C30,Customer_Dim!A:A,Customer_Dim!B:B,"Not Found")} -> Theresa Campbell | O30: {=XLOOKUP(C30,Customer_Dim!A:A,Customer_Dim!E:E,"Not Found")} -> New Brian | P30: {=XLOOKUP(D30,Product_Dim!A:A,Product_Dim!B:B,"Not Found")} -> USB-C Fast Charger | Q30: {=XLOOKUP(D30,Product_Dim!A:A,Product_Dim!C:C,"Not Found")} -> Electronics | R30: {=XLOOKUP(E30,Store_Dim!A:A,Store_Dim!B:B,"Not Found")} -> South | S30: {=XLOOKUP(E30,Store_Dim!A:A,Store_Dim!D:D,"Not Found")} -> Outlet
A31: SALE29 | B31: 45509 | C31: CUST1348 | D31: PROD99 | E31: STORE3 | G31: 451.67 | H31: 0.15 | I31: =F31*G31 -> 0 | J31: =H31*(1-I31) -> 0.15 | K31: =TEXT(B31,"mmm") -> Aug | L31: =YEAR(B31) -> 2024 | N31: {=XLOOKUP(C31,Customer_Dim!A:A,Customer_Dim!B:B,"Not Found")} -> Sherry Cabrera | O31: {=XLOOKUP(C31,Customer_Dim!A:A,Customer_Dim!E:E,"Not Found")} -> Shannonview | P31: {=XLOOKUP(D31,Product_Dim!A:A,Product_Dim!B:B,"Not Found")} -> Stainless Steel Cookware Set | Q31: {=XLOOKUP(D31,Product_Dim!A:A,Product_Dim!C:C,"Not Found")} -> Home | R31: {=XLOOKUP(E31,Store_Dim!A:A,Store_Dim!B:B,"Not Found")} -> North | S31: {=XLOOKUP(E31,Store_Dim!A:A,Store_Dim!D:D,"Not Found")} -> Outlet
A32: SALE30 | B32: 45510 | C32: CUST1028 | D32: PROD5 | E32: STORE19 | F32: 1 | G32: 429.38 | H32: 0.13 | I32: =F32*G32 -> 429.38 | J32: =H32*(1-I32) -> -55.6894 | K32: =TEXT(B32,"mmm") -> Aug | L32: =YEAR(B32) -> 2024 | N32: {=XLOOKUP(C32,Customer_Dim!A:A,Customer_Dim!B:B,"Not Found")} -> Joshua Ryan | O32: {=XLOOKUP(C32,Customer_Dim!A:A,Customer_Dim!E:E,"Not Found")} -> New David | P32: {=XLOOKUP(D32,Product_Dim!A:A,Product_Dim!B:B,"Not Found")} -> Men's Leather Belt | Q32: {=XLOOKUP(D32,Product_Dim!A:A,Product_Dim!C:C,"Not Found")} -> Clothing | R32: {=XLOOKUP(E32,Store_Dim!A:A,Store_Dim!B:B,"Not Found")} -> East | S32: {=XLOOKUP(E32,Store_Dim!A:A,Store_Dim!D:D,"Not Found")} -> Online
A33: SALE31 | B33: 45511 | C33: CUST1412 | D33: PROD53 | E33: STORE12 | F33: 2 | G33: 148.96 | H33: 0.03 | I33: =F33*G33 -> 297.92 | J33: =H33*(1-I33) -> -8.9076 | K33: =TEXT(B33,"mmm") -> Aug | L33: =YEAR(B33) -> 2024 | N33: {=XLOOKUP(C33,Customer_Dim!A:A,Customer_Dim!B:B,"Not Found")} -> Shane Brown | O33: {=XLOOKUP(C33,Customer_Dim!A:A,Customer_Dim!E:E,"Not Found")} -> East Andrea | P33: {=XLOOKUP(D33,Product_Dim!A:A,Product_Dim!B:B,"Not Found")} -> Men's Track Pants | Q33: {=XLOOKUP(D33,Product_Dim!A:A,Product_Dim!C:C,"Not Found")} -> Clothing | R33: {=XLOOKUP(E33,Store_Dim!A:A,Store_Dim!B:B,"Not Found")} -> North | S33: {=XLOOKUP(E33,Store_Dim!A:A,Store_Dim!D:D,"Not Found")} -> Online
A34: SALE32 | B34: 45512 | C34: CUST1398 | D34: PROD75 | E34: STORE8 | F34: 4 | G34: 313.83 | H34: 0.08 | I34: =F34*G34 -> 1255.32 | J34: =H34*(1-I34) -> -100.3456 | K34: =TEXT(B34,"mmm") -> Aug | L34: =YEAR(B34) -> 2024 | N34: {=XLOOKUP(C34,Customer_Dim!A:A,Customer_Dim!B:B,"Not Found")} -> Jennifer Johnson | O34: {=XLOOKUP(C34,Customer_Dim!A:A,Customer_Dim!E:E,"Not Found")} -> Cheyenneborough | P34: {=XLOOKUP(D34,Product_Dim!A:A,Product_Dim!B:B,"Not Found")} -> Women's Ankle Boots | Q34: {=XLOOKUP(D34,Product_Dim!A:A,Product_Dim!C:C,"Not Found")} -> Clothing | R34: {=XLOOKUP(E34,Store_Dim!A:A,Store_Dim!B:B,"Not Found")} -> West | S34: {=XLOOKUP(E34,Store_Dim!A:A,Store_Dim!D:D,"Not Found")} -> Online
A35: SALE33 | B35: 45513 | C35: CUST1453 | D35: PROD12 | E35: STORE6 | F35: 2 | G35: 717.31 | H35: 0.15 | I35: =F35*G35 -> 1434.62 | J35: =H35*(1-I35) -> -215.043 | K35: =TEXT(B35,"mmm") -> Aug | L35: =YEAR(B35) -> 2024 | N35: {=XLOOKUP(C35,Customer_Dim!A:A,Customer_Dim!B:B,"Not Found")} -> April Phillips | O35: {=XLOOKUP(C35,Customer_Dim!A:A,Customer_Dim!E:E,"Not Found")} -> Lake Carolyn | P35: {=XLOOKUP(D35,Product_Dim!A:A,Product_Dim!B:B,"Not Found")} -> Hair Strengthening Shampoo | Q35: {=XLOOKUP(D35,Product_Dim!A:A,Product_Dim!C:C,"Not Found")} -> Beauty | R35: {=XLOOKUP(E35,Store_Dim!A:A,Store_Dim!B:B,"Not Found")} -> East | S35: {=XLOOKUP(E35,Store_Dim!A:A,Store_Dim!D:D,"Not Found")} -> Online
A36: SALE34 | B36: 45514 | C36: CUST1344 | D36: PROD79 | E36: STORE1 | G36: 873.22 | H36: 0.18 | I36: =F36*G36 -> 0 | J36: =H36*(1-I36) -> 0.18 | K36: =TEXT(B36,"mmm") -> Aug | L36: =YEAR(B36) -> 2024 | N36: {=XLOOKUP(C36,Customer_Dim!A:A,Customer_Dim!B:B,"Not Found")} -> Evelyn Brown | O36: {=XLOOKUP(C36,Customer_Dim!A:A,Customer_Dim!E:E,"Not Found")} -> West Victoriaborough | P36: {=XLOOKUP(D36,Product_Dim!A:A,Product_Dim!B:B,"Not Found")} -> Decorative Lamp Shade | Q36: {=XLOOKUP(D36,Product_Dim!A:A,Product_Dim!C:C,"Not Found")} -> Home | R36: {=XLOOKUP(E36,Store_Dim!A:A,Store_Dim!B:B,"Not Found")} -> North | S36: {=XLOOKUP(E36,Store_Dim!A:A,Store_Dim!D:D,"Not Found")} -> Flagship
A37: SALE35 | B37: 45515 | C37: CUST1218 | D37: PROD16 | E37: STORE3 | F37: 4 | G37: 109.36 | H37: 0.19 | I37: =F37*G37 -> 437.44 | J37: =H37*(1-I37) -> -82.9236 | K37: =TEXT(B37,"mmm") -> Aug | L37: =YEAR(B37) -> 2024 | N37: {=XLOOKUP(C37,Customer_Dim!A:A,Customer_Dim!B:B,"Not Found")} -> Julia Jackson | O37: {=XLOOKUP(C37,Customer_Dim!A:A,Customer_Dim!E:E,"Not Found")} -> Edwardland | P37: {=XLOOKUP(D37,Product_Dim!A:A,Product_Dim!B:B,"Not Found")} -> Not Found | Q37: {=XLOOKUP(D37,Product_Dim!A:A,Product_Dim!C:C,"Not Found")} -> Not Found | R37: {=XLOOKUP(E37,Store_Dim!A:A,Store_Dim!B:B,"Not Found")} -> North | S37: {=XLOOKUP(E37,Store_Dim!A:A,Store_Dim!D:D,"Not Found")} -> Outlet
A38: SALE36 | B38: 45516 | C38: CUST1086 | D38: PROD5 | E38: STORE7 | F38: 3 | G38: 559.52 | H38: 0.16 | I38: =F38*G38 -> 1678.56 | J38: =H38*(1-I38) -> -268.4096 | K38: =TEXT(B38,"mmm") -> Aug | L38: =YEAR(B38) -> 2024 | N38: {=XLOOKUP(C38,Customer_Dim!A:A,Customer_Dim!B:B,"Not Found")} -> Tammy Miller MD | O38: {=XLOOKUP(C38,Customer_Dim!A:A,Customer_Dim!E:E,"Not Found")} -> Austinfurt | P38: {=XLOOKUP(D38,Product_Dim!A:A,Product_Dim!B:B,"Not Found")} -> Men's Leather Belt | Q38: {=XLOOKUP(D38,Product_Dim!A:A,Product_Dim!C:C,"Not Found")} -> Clothing | R38: {=XLOOKUP(E38,Store_Dim!A:A,Store_Dim!B:B,"Not Found")} -> South | S38: {=XLOOKUP(E38,Store_Dim!A:A,Store_Dim!D:D,"Not Found")} -> Online
A39: SALE37 | B39: 45517 | C39: CUST1492 | D39: PROD10 | E39: STORE17 | F39: 3 | G39: 121.76 | H39: 0.27 | I39: =F39*G39 -> 365.28 | J39: =H39*(1-I39) -> -98.3556 | K39: =TEXT(B39,"mmm") -> Aug | L39: =YEAR(B39) -> 2024 | N39: {=XLOOKUP(C39,Customer_Dim!A:A,Customer_Dim!B:B,"Not Found")} -> Darrell Miller | O39: {=XLOOKUP(C39,Customer_Dim!A:A,Customer_Dim!E:E,"Not Found")} -> Port Carol | P39: {=XLOOKUP(D39,Product_Dim!A:A,Product_Dim!B:B,"Not Found")} -> Ceramic Kitchen Bowl Set | Q39: {=XLOOKUP(D39,Product_Dim!A:A,Product_Dim!C:C,"Not Found")} -> Home | R39: {=XLOOKUP(E39,Store_Dim!A:A,Store_Dim!B:B,"Not Found")} -> North | S39: {=XLOOKUP(E39,Store_Dim!A:A,Store_Dim!D:D,"Not Found")} -> Flagship
A40: SALE38 | B40: 45518 | C40: CUST1189 | D40: PROD33 | E40: STORE13 | F40: 4 | G40: 735.32 | H40: 0.06 | I40: =F40*G40 -> 2941.28 | J40: =H40*(1-I40) -> -176.4168 | K40: =TEXT(B40,"mmm") -> Aug | L40: =YEAR(B40) -> 2024 | N40: {=XLOOKUP(C40,Customer_Dim!A:A,Customer_Dim!B:B,"Not Found")} -> Daniel Austin | O40: {=XLOOKUP(C40,Customer_Dim!A:A,Customer_Dim!E:E,"Not Found")} -> Lake Howardberg | P40: {=XLOOKUP(D40,Product_Dim!A:A,Product_Dim!B:B,"Not Found")} -> Modern Wall Clock | Q40: {=XLOOKUP(D40,Product_Dim!A:A,Product_Dim!C:C,"Not Found")} -> Home | R40: {=XLOOKUP(E40,Store_Dim!A:A,Store_Dim!B:B,"Not Found")} -> East | S40: {=XLOOKUP(E40,Store_Dim!A:A,Store_Dim!D:D,"Not Found")} -> Flagship
...

Sheet CUSTOMER_PIVOT_TABLE

Sheet STORE_PIVOT_TABLE
